Workbook

Sheet Tableau de bord
A1: Tableau de bord stock & chantiers
A3: Articles actifs | B3: =COUNTIF(Articles!K5:K204,"Oui") -> 200 | C3: Alertes seuil | D3: =COUNTIF('Stock Global'!M5:M204,"À commander") -> 1 | E3: Valeur stock | F3: =SUM('Stock Global'!N5:N204) -> 907.00 € | G3: Stock négatif | H3: =COUNTIF('Stock Global'!M5:M204,"Stock négatif") -> 0
A6: À commander ? | B6: Référence | C6: Désignation | D6: Stock actuel | E6: Seuil | F6: Statut
A7: =IF('Stock Global'!M5="À commander","Oui","") | D7: 0 | E7: ='Stock Global'!K5 -> 4 | F7: ='Stock Global'!M5 -> OK
A8: =IF('Stock Global'!M6="À commander","Oui","") | B8: ='Stock Global'!A6 -> PERF-001 | C8: ='Stock Global'!B6 -> Perforateur SDS | D8: 0 | E8: ='Stock Global'!K6 -> 1 | F8: ='Stock Global'!M6 -> OK
A9: =IF('Stock Global'!M7="À commander","Oui","") | B9: ='Stock Global'!A7 -> GANT-L | C9: ='Stock Global'!B7 -> Gants taille L | D9: ='Stock Global'!J7 -> 50 | E9: ='Stock Global'!K7 -> 15 | F9: ='Stock Global'!M7 -> OK
A10: =IF('Stock Global'!M8="À commander","Oui","") | B10: ='Stock Global'!A8 -> 12345 | C10: ='Stock Global'!B8 -> Quentin | D10: ='Stock Global'!J8 -> 10 | E10: ='Stock Global'!K8 -> 10 | F10: ='Stock Global'!M8 -> OK
A11: =IF('Stock Global'!M9="À commander","Oui","") -> Oui | B11: ='Stock Global'!A9 -> 4969272 | C11: ='Stock Global'!B9 -> teben | D11: ='Stock Global'!J9 -> 1 | E11: ='Stock Global'!K9 -> 2 | F11: ='Stock Global'!M9 -> À commander
A12: =IF('Stock Global'!M10="À commander","Oui","") | B12: ='Stock Global'!A10 | C12: ='Stock Global'!B10 | D12: ='Stock Global'!J10 | E12: ='Stock Global'!K10 | F12: ='Stock Global'!M10
A13: =IF('Stock Global'!M11="À commander","Oui","") | B13: ='Stock Global'!A11 | C13: ='Stock Global'!B11 | D13: ='Stock Global'!J11 | E13: ='Stock Global'!K11 | F13: ='Stock Global'!M11
A14: =IF('Stock Global'!M12="À commander","Oui","") | B14: ='Stock Global'!A12 | C14: ='Stock Global'!B12 | D14: ='Stock Global'!J12 | E14: ='Stock Global'!K12 | F14: ='Stock Global'!M12
A15: =IF('Stock Global'!M13="À commander","Oui","") | B15: ='Stock Global'!A13 | C15: ='Stock Global'!B13 | D15: ='Stock Global'!J13 | E15: ='Stock Global'!K13 | F15: ='Stock Global'!M13
A16: =IF('Stock Global'!M14="À commander","Oui","") | B16: ='Stock Global'!A14 | C16: ='Stock Global'!B14 | D16: ='Stock Global'!J14 | E16: ='Stock Global'!K14 | F16: ='Stock Global'!M14
A17: =IF('Stock Global'!M15="À commander","Oui","") | B17: ='Stock Global'!A15 | C17: ='Stock Global'!B15 | D17: ='Stock Global'!J15 | E17: ='Stock Global'!K15 | F17: ='Stock Global'!M15
A18: =IF('Stock Global'!M16="À commander","Oui","") | B18: ='Stock Global'!A16 | C18: ='Stock Global'!B16 | D18: ='Stock Global'!J16 | E18: ='Stock Global'!K16 | F18: ='Stock Global'!M16
A19: =IF('Stock Global'!M17="À commander","Oui","") | B19: ='Stock Global'!A17 | C19: ='Stock Global'!B17 | D19: ='Stock Global'!J17 | E19: ='Stock Global'!K17 | F19: ='Stock Global'!M17
A20: =IF('Stock Global'!M18="À commander","Oui","") | B20: ='Stock Global'!A18 | C20: ='Stock Global'!B18 | D20: ='Stock Global'!J18 | E20: ='Stock Global'!K18 | F20: ='Stock Global'!M18
... A26: =IF('Stock Global'!M24="À commander","Oui","") | B26: ='Stock Global'!A24 | C26: ='Stock Global'!B24 | D26: ='Stock Global'!J24 | E26: ='Stock Global'!K24 | F26: ='Stock Global'!M24
A30: Résumé par chantier | B30: Départs | C30: Retours | D30: Reste sur chantier | E30: Valeur départs
A31: ='Paramètres'!D4 -> Chantier A | B31: =SUMIFS(Mouvements!$G:$G,Mouvements!$E:$E,A31,Mouvements!$F:$F,"Départ") -> 104 | C31: =SUMIFS(Mouvements!$G:$G,Mouvements!$E:$E,A31,Mouvements!$F:$F,"Retour") -> 0 | D31: =B31-C31 -> 104 | E31: =SUMIFS(Mouvements!$J:$J,Mouvements!$E:$E,A31,Mouvements!$F:$F,"Départ") -> 1,220.00 €
A32: ='Paramètres'!D5 -> Chantier B | B32: =SUMIFS(Mouvements!$G:$G,Mouvements!$E:$E,A32,Mouvements!$F:$F,"Départ") -> 0 | C32: =SUMIFS(Mouvements!$G:$G,Mouvements!$E:$E,A32,Mouvements!$F:$F,"Retour") -> 0 | D32: =B32-C32 -> 0 | E32: =SUMIFS(Mouvements!$J:$J,Mouvements!$E:$E,A32,Mouvements!$F:$F,"Départ") -> 0.00 €
A33: ='Paramètres'!D6 -> Chantier C | B33: =SUMIFS(Mouvements!$G:$G,Mouvements!$E:$E,A33,Mouvements!$F:$F,"Départ") -> 0 | C33: =SUMIFS(Mouvements!$G:$G,Mouvements!$E:$E,A33,Mouvements!$F:$F,"Retour") -> 0 | D33: =B33-C33 -> 0 | E33: =SUMIFS(Mouvements!$J:$J,Mouvements!$E:$E,A33,Mouvements!$F:$F,"Départ") -> 0.00 €
A34: ='Paramètres'!D7 -> Atelier | B34: =SUMIFS(Mouvements!$G:$G,Mouvements!$E:$E,A34,Mouvements!$F:$F,"Départ") -> 0 | C34: =SUMIFS(Mouvements!$G:$G,Mouvements!$E:$E,A34,Mouvements!$F:$F,"Retour") -> 0 | D34: =B34-C34 -> 0 | E34: =SUMIFS(Mouvements!$J:$J,Mouvements!$E:$E,A34,Mouvements!$F:$F,"Départ") -> 0.00 €
A35: ='Paramètres'!D8 -> Dépôt | B35: =SUMIFS(Mouvements!$G:$G,Mouvements!$E:$E,A35,Mouvements!$F:$F,"Départ") -> 0 | C35: =SUMIFS(Mouvements!$G:$G,Mouvements!$E:$E,A35,Mouvements!$F:$F,"Retour") -> 0 | D35: =B35-C35 -> 0 | E35: =SUMIFS(Mouvements!$J:$J,Mouvements!$E:$E,A35,Mouvements!$F:$F,"Départ") -> 0.00 €
A36: ='Paramètres'!D9 | B36: =SUMIFS(Mouvements!$G:$G,Mouvements!$E:$E,A36,Mouvements!$F:$F,"Départ") -> 0 | C36: =SUMIFS(Mouvements!$G:$G,Mouvements!$E:$E,A36,Mouvements!$F:$F,"Retour") -> 0 | D36: =B36-C36 -> 0 | E36: =SUMIFS(Mouvements!$J:$J,Mouvements!$E:$E,A36,Mouvements!$F:$F,"Départ") -> 0.00 €
A37: ='Paramètres'!D10 | B37: =SUMIFS(Mouvements!$G:$G,Mouvements!$E:$E,A37,Mouvements!$F:$F,"Départ") -> 0 | C37: =SUMIFS(Mouvements!$G:$G,Mouvements!$E:$E,A37,Mouvements!$F:$F,"Retour") -> 0 | D37: =B37-C37 -> 0 | E37: =SUMIFS(Mouvements!$J:$J,Mouvements!$E:$E,A37,Mouvements!$F:$F,"Départ") -> 0.00 €
A38: ='Paramètres'!D11 | B38: =SUMIFS(Mouvements!$G:$G,Mouvements!$E:$E,A38,Mouvements!$F:$F,"Départ") -> 0 | C38: =SUMIFS(Mouvements!$G:$G,Mouvements!$E:$E,A38,Mouvements!$F:$F,"Retour") -> 0 | D38: =B38-C38 -> 0 | E38: =SUMIFS(Mouvements!$J:$J,Mouvements!$E:$E,A38,Mouvements!$F:$F,"Départ") -> 0.00 €
A39: ='Paramètres'!D12 | B39: =SUMIFS(Mouvements!$G:$G,Mouvements!$E:$E,A39,Mouvements!$F:$F,"Départ") -> 0 | C39: =SUMIFS(Mouvements!$G:$G,Mouvements!$E:$E,A39,Mouvements!$F:$F,"Retour") -> 0 | D39: =B39-C39 -> 0 | E39: =SUMIFS(Mouvements!$J:$J,Mouvements!$E:$E,A39,Mouvements!$F:$F,"Départ") -> 0.00 €
A40: ='Paramètres'!D13 | B40: =SUMIFS(Mouvements!$G:$G,Mouvements!$E:$E,A40,Mouvements!$F:$F,"Départ") -> 0 | C40: =SUMIFS(Mouvements!$G:$G,Mouvements!$E:$E,A40,Mouvements!$F:$F,"Retour") -> 0 | D40: =B40-C40 -> 0 | E40: =SUMIFS(Mouvements!$J:$J,Mouvements!$E:$E,A40,Mouvements!$F:$F,"Départ") -> 0.00 €

Sheet Paramètres
A1: Paramètres et listes déroulantes
A3: Types de mouvement | B3: Catégories | C3: Unités | D3: Chantiers | E3: Emplacements
A4: Départ | B4: Outillage | C4: u | D4: Chantier A | E4: Dépôt principal
A5: Retour | B5: Consommable | C5: paire | D5: Chantier B | E5: Fourgon
A6: Entrée stock | B6: Matériaux | C6: ml | D6: Chantier C | E6: Atelier
A7: Correction + | B7: EPI | C7: m² | D7: Atelier | E7: Zone A
A8: Correction - | B8: Location | C8: m³ | D8: Dépôt | E8: Zone B
B9: Autre | C9: kg
C10: L
C11: boîte
C12: palette
A105: Ajoute ici tes types, catégories, unités, chantiers ou emplacements si besoin.

Sheet Articles
A1: Base articles - références, seuils et stock initial
A2: Saisir une ligne par article. La référence est recommandée pour automatiser les mouvements.
A4: Référence | B4: Désignation | C4: Catégorie | D4: Unité | E4: Emplacement | F4: Stock initial | G4: Seuil minimum | H4: Prix unitaire estimé | I4: Fournisseur | J4: Code-barres / QR | K4: Actif ?
A5: VIS-6X60 | B5: Vis béton 6x60 | C5: Consommable | D5: boîte | E5: Dépôt principal | F5: 12 | G5: 4 | H5: 8.5 | K5: Oui
A6: PERF-001 | B6: Perforateur SDS | C6: Outillage | D6: u | E6: Atelier | F6: 3 | G6: 1 | H6: 180 | K6: Oui
A7: GANT-L | B7: Gants taille L | C7: EPI | D7: paire | E7: Dépôt principal | F7: 50 | G7: 15 | H7: 2.2 | I7: Balitrant | K7: Oui
A8: 12345 | B8: Quentin | C8: Consommable | D8: u | E8: Dépôt principal | F8: 10 | G8: 10 | H8: 10 | I8: Yesss | K8: Oui
A9: 4969272 | B9: teben | C9: Autre | D9: u | E9: Dépôt principal | F9: 5 | G9: 2 | H9: 55 | I9: yesss | K9: Oui
K10: Oui
K11: Oui
K12: Oui
K13: Oui
K14: Oui
K15: Oui
K16: Oui
K17: Oui
K18: Oui
K19: Oui
K20: Oui
K21: Oui
... K204: Oui

Sheet Mouvements
A1: Journal des mouvements - départs, retours et entrées
A2: Départ = sortie vers chantier. Retour = retour au dépôt. Entrée stock = achat/réassort.
A4: Date | B4: Référence | C4: Désignation si pas de réf. | D4: Désignation trouvée | E4: Chantier | F4: Type | G4: Quantité | H4: Sens | I4: Impact stock | J4: Valeur mouvement | K4: Saisi par | L4: Observation | M4: Statut
C5: Vis | D5: =IF(B5="","",IFERROR(VLOOKUP(B5,Articles!$A$5:$K$204,2,FALSE),"Référence inconnue")) | E5: Chantier A | F5: Entrée stock | G5: 100 | H5: =IF(F5="Départ",-1,IF(F5="Retour",1,IF(F5="Entrée stock",1,IF(F5="Correction +",1,IF(F5="Correction -",-1,0))))) -> 1 | I5: =IF(G5="","",G5*H5) -> 100 | J5: =IF(B5="","",IFERROR(G5*VLOOKUP(B5,Articles!$A$5:$K$204,8,FALSE),0)) | M5: =IF(AND(B5="",C5=""),"À compléter",IF(G5<=0,"Qté manquante",IF(F5="","Type manquant","OK"))) -> OK
B6: 12345 | D6: =IF(B6="","",IFERROR(VLOOKUP(B6,Articles!$A$5:$K$204,2,FALSE),"Référence inconnue")) -> Quentin | E6: Chantier A | F6: Départ | G6: 100 | H6: =IF(F6="Départ",-1,IF(F6="Retour",1,IF(F6="Entrée stock",1,IF(F6="Correction +",1,IF(F6="Correction -",-1,0))))) -> -1 | I6: =IF(G6="","",G6*H6) -> -100 | J6: =IF(B6="","",IFERROR(G6*VLOOKUP(B6,Articles!$A$5:$K$204,8,FALSE),0)) -> 1,000.00 € | M6: =IF(AND(B6="",C6=""),"À compléter",IF(G6<=0,"Qté manquante",IF(F6="","Type manquant","OK"))) -> OK
B7: 12345 | D7: =IF(B7="","",IFERROR(VLOOKUP(B7,Articles!$A$5:$K$204,2,FALSE),"Référence inconnue")) -> Quentin | E7: Atelier | F7: Entrée stock | G7: 100 | H7: =IF(F7="Départ",-1,IF(F7="Retour",1,IF(F7="Entrée stock",1,IF(F7="Correction +",1,IF(F7="Correction -",-1,0))))) -> 1 | I7: =IF(G7="","",G7*H7) -> 100 | J7: =IF(B7="","",IFERROR(G7*VLOOKUP(B7,Articles!$A$5:$K$204,8,FALSE),0)) -> 1,000.00 € | M7: =IF(AND(B7="",C7=""),"À compléter",IF(G7<=0,"Qté manquante",IF(F7="","Type manquant","OK"))) -> OK
B8: 4969272 | D8: =IF(B8="","",IFERROR(VLOOKUP(B8,Articles!$A$5:$K$204,2,FALSE),"Référence inconnue")) -> teben | E8: Chantier A | F8: Départ | G8: 4 | H8: =IF(F8="Départ",-1,IF(F8="Retour",1,IF(F8="Entrée stock",1,IF(F8="Correction +",1,IF(F8="Correction -",-1,0))))) -> -1 | I8: =IF(G8="","",G8*H8) -> -4 | J8: =IF(B8="","",IFERROR(G8*VLOOKUP(B8,Articles!$A$5:$K$204,8,FALSE),0)) -> 220.00 € | M8: =IF(AND(B8="",C8=""),"À compléter",IF(G8<=0,"Qté manquante",IF(F8="","Type manquant","OK"))) -> OK
D9: =IF(B9="","",IFERROR(VLOOKUP(B9,Articles!$A$5:$K$204,2,FALSE),"Référence inconnue")) | H9: =IF(F9="Départ",-1,IF(F9="Retour",1,IF(F9="Entrée stock",1,IF(F9="Correction +",1,IF(F9="Correction -",-1,0))))) -> 0 | I9: =IF(G9="","",G9*H9) | J9: =IF(B9="","",IFERROR(G9*VLOOKUP(B9,Articles!$A$5:$K$204,8,FALSE),0)) | M9: =IF(AND(B9="",C9=""),"À compléter",IF(G9<=0,"Qté manquante",IF(F9="","Type manquant","OK"))) -> À compléter
D10: =IF(B10="","",IFERROR(VLOOKUP(B10,Articles!$A$5:$K$204,2,FALSE),"Référence inconnue")) | H10: =IF(F10="Départ",-1,IF(F10="Retour",1,IF(F10="Entrée stock",1,IF(F10="Correction +",1,IF(F10="Correction -",-1,0))))) -> 0 | I10: =IF(G10="","",G10*H10) | J10: =IF(B10="","",IFERROR(G10*VLOOKUP(B10,Articles!$A$5:$K$204,8,FALSE),0)) | M10: =IF(AND(B10="",C10=""),"À compléter",IF(G10<=0,"Qté manquante",IF(F10="","Type manquant","OK"))) -> À compléter
D11: =IF(B11="","",IFERROR(VLOOKUP(B11,Articles!$A$5:$K$204,2,FALSE),"Référence inconnue")) | H11: =IF(F11="Départ",-1,IF(F11="Retour",1,IF(F11="Entrée stock",1,IF(F11="Correction +",1,IF(F11="Correction -",-1,0))))) -> 0 | I11: =IF(G11="","",G11*H11) | J11: =IF(B11="","",IFERROR(G11*VLOOKUP(B11,Articles!$A$5:$K$204,8,FALSE),0)) | M11: =IF(AND(B11="",C11=""),"À compléter",IF(G11<=0,"Qté manquante",IF(F11="","Type manquant","OK"))) -> À compléter
D12: =IF(B12="","",IFERROR(VLOOKUP(B12,Articles!$A$5:$K$204,2,FALSE),"Référence inconnue")) | H12: =IF(F12="Départ",-1,IF(F12="Retour",1,IF(F12="Entrée stock",1,IF(F12="Correction +",1,IF(F12="Correction -",-1,0))))) -> 0 | I12: =IF(G12="","",G12*H12) | J12: =IF(B12="","",IFERROR(G12*VLOOKUP(B12,Articles!$A$5:$K$204,8,FALSE),0)) | M12: =IF(AND(B12="",C12=""),"À compléter",IF(G12<=0,"Qté manquante",IF(F12="","Type manquant","OK"))) -> À compléter
D13: =IF(B13="","",IFERROR(VLOOKUP(B13,Articles!$A$5:$K$204,2,FALSE),"Référence inconnue")) | H13: =IF(F13="Départ",-1,IF(F13="Retour",1,IF(F13="Entrée stock",1,IF(F13="Correction +",1,IF(F13="Correction -",-1,0))))) -> 0 | I13: =IF(G13="","",G13*H13) | J13: =IF(B13="","",IFERROR(G13*VLOOKUP(B13,Articles!$A$5:$K$204,8,FALSE),0)) | M13: =IF(AND(B13="",C13=""),"À compléter",IF(G13<=0,"Qté manquante",IF(F13="","Type manquant","OK"))) -> À compléter
D14: =IF(B14="","",IFERROR(VLOOKUP(B14,Articles!$A$5:$K$204,2,FALSE),"Référence inconnue")) | H14: =IF(F14="Départ",-1,IF(F14="Retour",1,IF(F14="Entrée stock",1,IF(F14="Correction +",1,IF(F14="Correction -",-1,0))))) -> 0 | I14: =IF(G14="","",G14*H14) | J14: =IF(B14="","",IFERROR(G14*VLOOKUP(B14,Articles!$A$5:$K$204,8,FALSE),0)) | M14: =IF(AND(B14="",C14=""),"À compléter",IF(G14<=0,"Qté manquante",IF(F14="","Type manquant","OK"))) -> À compléter
D15: =IF(B15="","",IFERROR(VLOOKUP(B15,Articles!$A$5:$K$204,2,FALSE),"Référence inconnue")) | H15: =IF(F15="Départ",-1,IF(F15="Retour",1,IF(F15="Entrée stock",1,IF(F15="Correction +",1,IF(F15="Correction -",-1,0))))) -> 0 | I15: =IF(G15="","",G15*H15) | J15: =IF(B15="","",IFERROR(G15*VLOOKUP(B15,Articles!$A$5:$K$204,8,FALSE),0)) | M15: =IF(AND(B15="",C15=""),"À compléter",IF(G15<=0,"Qté manquante",IF(F15="","Type manquant","OK"))) -> À compléter
D16: =IF(B16="","",IFERROR(VLOOKUP(B16,Articles!$A$5:$K$204,2,FALSE),"Référence inconnue")) | H16: =IF(F16="Départ",-1,IF(F16="Retour",1,IF(F16="Entrée stock",1,IF(F16="Correction +",1,IF(F16="Correction -",-1,0))))) -> 0 | I16: =IF(G16="","",G16*H16) | J16: =IF(B16="","",IFERROR(G16*VLOOKUP(B16,Articles!$A$5:$K$204,8,FALSE),0)) | M16: =IF(AND(B16="",C16=""),"À compléter",IF(G16<=0,"Qté manquante",IF(F16="","Type manquant","OK"))) -> À compléter
D17: =IF(B17="","",IFERROR(VLOOKUP(B17,Articles!$A$5:$K$204,2,FALSE),"Référence inconnue")) | H17: =IF(F17="Départ",-1,IF(F17="Retour",1,IF(F17="Entrée stock",1,IF(F17="Correction +",1,IF(F17="Correction -",-1,0))))) -> 0 | I17: =IF(G17="","",G17*H17) | J17: =IF(B17="","",IFERROR(G17*VLOOKUP(B17,Articles!$A$5:$K$204,8,FALSE),0)) | M17: =IF(AND(B17="",C17=""),"À compléter",IF(G17<=0,"Qté manquante",IF(F17="","Type manquant","OK"))) -> À compléter
D18: =IF(B18="","",IFERROR(VLOOKUP(B18,Articles!$A$5:$K$204,2,FALSE),"Référence inconnue")) | H18: =IF(F18="Départ",-1,IF(F18="Retour",1,IF(F18="Entrée stock",1,IF(F18="Correction +",1,IF(F18="Correction -",-1,0))))) -> 0 | I18: =IF(G18="","",G18*H18) | J18: =IF(B18="","",IFERROR(G18*VLOOKUP(B18,Articles!$A$5:$K$204,8,FALSE),0)) | M18: =IF(AND(B18="",C18=""),"À compléter",IF(G18<=0,"Qté manquante",IF(F18="","Type manquant","OK"))) -> À compléter
D19: =IF(B19="","",IFERROR(VLOOKUP(B19,Articles!$A$5:$K$204,2,FALSE),"Référence inconnue")) | H19: =IF(F19="Départ",-1,IF(F19="Retour",1,IF(F19="Entrée stock",1,IF(F19="Correction +",1,IF(F19="Correction -",-1,0))))) -> 0 | I19: =IF(G19="","",G19*H19) | J19: =IF(B19="","",IFERROR(G19*VLOOKUP(B19,Articles!$A$5:$K$204,8,FALSE),0)) | M19: =IF(AND(B19="",C19=""),"À compléter",IF(G19<=0,"Qté manquante",IF(F19="","Type manquant","OK"))) -> À compléter
D20: =IF(B20="","",IFERROR(VLOOKUP(B20,Articles!$A$5:$K$204,2,FALSE),"Référence inconnue")) | H20: =IF(F20="Départ",-1,IF(F20="Retour",1,IF(F20="Entrée stock",1,IF(F20="Correction +",1,IF(F20="Correction -",-1,0))))) -> 0 | I20: =IF(G20="","",G20*H20) | J20: =IF(B20="","",IFERROR(G20*VLOOKUP(B20,Articles!$A$5:$K$204,8,FALSE),0)) | M20: =IF(AND(B20="",C20=""),"À compléter",IF(G20<=0,"Qté manquante",IF(F20="","Type manquant","OK"))) -> À compléter
... D504: =IF(B504="","",IFERROR(VLOOKUP(B504,Articles!$A$5:$K$204,2,FALSE),"Référence inconnue")) | H504: =IF(F504="Départ",-1,IF(F504="Retour",1,IF(F504="Entrée stock",1,IF(F504="Correction +",1,IF(F504="Correction -",-1,0))))) -> 0 | I504: =IF(G504="","",G504*H504) | J504: =IF(B504="","",IFERROR(G504*VLOOKUP(B504,Articles!$A$5:$K$204,8,FALSE),0)) | M504: =IF(AND(B504="",C504=""),"À compléter",IF(G504<=0,"Qté manquante",IF(F504="","Type manquant","OK"))) -> À compléter

Sheet Stock Global
A1: Stock global automatique
A4: Référence | B4: Désignation | C4: Catégorie | D4: Unité | E4: Emplacement | F4: Stock initial | G4: Départs | H4: Retours | I4: Entrées/Corrections | J4: Stock actuel | K4: Seuil | L4: Écart seuil | M4: Statut | N4: Valeur stock
A5: =Articles!A5 -> VIS-6X60 | B5: =Articles!B5 -> Vis béton 6x60 | C5: =Articles!C5 -> Consommable | D5: =Articles!D5 -> boîte | E5: =Articles!E5 -> Dépôt principal | F5: =Articles!F5 -> 12 | G5: =SUMIFS(Mouvements!$G:$G,Mouvements!$B:$B,A5,Mouvements!$F:$F,"Départ") -> 0 | H5: =SUMIFS(Mouvements!$G:$G,Mouvements!$B:$B,A5,Mouvements!$F:$F,"Retour") -> 0 | I5: =SUMIFS(Mouvements!$I:$I,Mouvements!$B:$B,A5,Mouvements!$F:$F,"Entrée stock")+SUMIFS(Mouvements!$I:$I,Mouvements!$B:$B,A5,Mouvements!$F:$F,"Correction +")+SUMIFS(Mouvements!$I:$I,Mouvements!$B:$B,A5,Mouvements!$F:$F,"Correction -") -> 0 | J5: =IF(A5="","",F5-G5+H5+I5) -> 12 | K5: =Articles!G5 -> 4 | L5: =IF(A5="","",J5-K5) -> 8 | M5: =IF(A5="","",IF(J5<0,"Stock négatif",IF(J5<K5,"À commander","OK"))) -> OK | N5: =IF(A5="","",J5*Articles!H5) -> 102.00 €
A6: =Articles!A6 -> PERF-001 | B6: =Articles!B6 -> Perforateur SDS | C6: =Articles!C6 -> Outillage | D6: =Articles!D6 -> u | E6: =Articles!E6 -> Atelier | F6: =Articles!F6 -> 3 | G6: =SUMIFS(Mouvements!$G:$G,Mouvements!$B:$B,A6,Mouvements!$F:$F,"Départ") -> 0 | H6: =SUMIFS(Mouvements!$G:$G,Mouvements!$B:$B,A6,Mouvements!$F:$F,"Retour") -> 0 | I6: =SUMIFS(Mouvements!$I:$I,Mouvements!$B:$B,A6,Mouvements!$F:$F,"Entrée stock")+SUMIFS(Mouvements!$I:$I,Mouvements!$B:$B,A6,Mouvements!$F:$F,"Correction +")+SUMIFS(Mouvements!$I:$I,Mouvements!$B:$B,A6,Mouvements!$F:$F,"Correction -") -> 0 | J6: =IF(A6="","",F6-G6+H6+I6) -> 3 | K6: =Articles!G6 -> 1 | L6: =IF(A6="","",J6-K6) -> 2 | M6: =IF(A6="","",IF(J6<0,"Stock négatif",IF(J6<K6,"À commander","OK"))) -> OK | N6: =IF(A6="","",J6*Articles!H6) -> 540.00 €
A7: =Articles!A7 -> GANT-L | B7: =Articles!B7 -> Gants taille L | C7: =Articles!C7 -> EPI | D7: =Articles!D7 -> paire | E7: =Articles!E7 -> Dépôt principal | F7: =Articles!F7 -> 50 | G7: =SUMIFS(Mouvements!$G:$G,Mouvements!$B:$B,A7,Mouvements!$F:$F,"Départ") -> 0 | H7: =SUMIFS(Mouvements!$G:$G,Mouvements!$B:$B,A7,Mouvements!$F:$F,"Retour") -> 0 | I7: =SUMIFS(Mouvements!$I:$I,Mouvements!$B:$B,A7,Mouvements!$F:$F,"Entrée stock")+SUMIFS(Mouvements!$I:$I,Mouvements!$B:$B,A7,Mouvements!$F:$F,"Correction +")+SUMIFS(Mouvements!$I:$I,Mouvements!$B:$B,A7,Mouvements!$F:$F,"Correction -") -> 0 | J7: =IF(A7="","",F7-G7+H7+I7) -> 50 | K7: =Articles!G7 -> 15 | L7: =IF(A7="","",J7-K7) -> 35 | M7: =IF(A7="","",IF(J7<0,"Stock négatif",IF(J7<K7,"À commander","OK"))) -> OK | N7: =IF(A7="","",J7*Articles!H7) -> 110.00 €
A8: =Articles!A8 -> 12345 | B8: =Articles!B8 -> Quentin | C8: =Articles!C8 -> Consommable | D8: =Articles!D8 -> u | E8: =Articles!E8 -> Dépôt principal | F8: =Articles!F8 -> 10 | G8: =SUMIFS(Mouvements!$G:$G,Mouvements!$B:$B,A8,Mouvements!$F:$F,"Départ") -> 100 | H8: =SUMIFS(Mouvements!$G:$G,Mouvements!$B:$B,A8,Mouvements!$F:$F,"Retour") -> 0 | I8: =SUMIFS(Mouvements!$I:$I,Mouvements!$B:$B,A8,Mouvements!$F:$F,"Entrée stock")+SUMIFS(Mouvements!$I:$I,Mouvements!$B:$B,A8,Mouvements!$F:$F,"Correction +")+SUMIFS(Mouvements!$I:$I,Mouvements!$B:$B,A8,Mouvements!$F:$F,"Correction -") -> 100 | J8: =IF(A8="","",F8-G8+H8+I8) -> 10 | K8: =Articles!G8 -> 10 | L8: =IF(A8="","",J8-K8) -> 0 | M8: =IF(A8="","",IF(J8<0,"Stock négatif",IF(J8<K8,"À commander","OK"))) -> OK | N8: =IF(A8="","",J8*Articles!H8) -> 100.00 €
A9: =Articles!A9 -> 4969272 | B9: =Articles!B9 -> teben | C9: =Articles!C9 -> Autre | D9: =Articles!D9 -> u | E9: =Articles!E9 -> Dépôt principal | F9: =Articles!F9 -> 5 | G9: =SUMIFS(Mouvements!$G:$G,Mouvements!$B:$B,A9,Mouvements!$F:$F,"Départ") -> 4 | H9: =SUMIFS(Mouvements!$G:$G,Mouvements!$B:$B,A9,Mouvements!$F:$F,"Retour") -> 0 | I9: =SUMIFS(Mouvements!$I:$I,Mouvements!$B:$B,A9,Mouvements!$F:$F,"Entrée stock")+SUMIFS(Mouvements!$I:$I,Mouvements!$B:$B,A9,Mouvements!$F:$F,"Correction +")+SUMIFS(Mouvements!$I:$I,Mouvements!$B:$B,A9,Mouvements!$F:$F,"Correction -") -> 0 | J9: =IF(A9="","",F9-G9+H9+I9) -> 1 | K9: =Articles!G9 -> 2 | L9: =IF(A9="","",J9-K9) -> -1 | M9: =IF(A9="","",IF(J9<0,"Stock négatif",IF(J9<K9,"À commander","OK"))) -> À commander | N9: =IF(A9="","",J9*Articles!H9) -> 55.00 €
A10: =Articles!A10 | B10: =Articles!B10 | C10: =Articles!C10 | D10: =Articles!D10 | E10: =Articles!E10 | F10: =Articles!F10 | G10: =SUMIFS(Mouvements!$G:$G,Mouvements!$B:$B,A10,Mouvements!$F:$F,"Départ") -> 0 | H10: =SUMIFS(Mouvements!$G:$G,Mouvements!$B:$B,A10,Mouvements!$F:$F,"Retour") -> 0 | I10: =SUMIFS(Mouvements!$I:$I,Mouvements!$B:$B,A10,Mouvements!$F:$F,"Entrée stock")+SUMIFS(Mouvements!$I:$I,Mouvements!$B:$B,A10,Mouvements!$F:$F,"Correction +")+SUMIFS(Mouvements!$I:$I,Mouvements!$B:$B,A10,Mouvements!$F:$F,"Correction -") -> 0 | J10: =IF(A10="","",F10-G10+H10+I10) | K10: =Articles!G10 | L10: =IF(A10="","",J10-K10) | M10: =IF(A10="","",IF(J10<0,"Stock négatif",IF(J10<K10,"À commander","OK"))) | N10: =IF(A10="","",J10*Articles!H10)
A11: =Articles!A11 | B11: =Articles!B11 | C11: =Articles!C11 | D11: =Articles!D11 | E11: =Articles!E11 | F11: =Articles!F11 | G11: =SUMIFS(Mouvements!$G:$G,Mouvements!$B:$B,A11,Mouvements!$F:$F,"Départ") -> 0 | H11: =SUMIFS(Mouvements!$G:$G,Mouvements!$B:$B,A11,Mouvements!$F:$F,"Retour") -> 0 | I11: =SUMIFS(Mouvements!$I:$I,Mouvements!$B:$B,A11,Mouvements!$F:$F,"Entrée stock")+SUMIFS(Mouvements!$I:$I,Mouvements!$B:$B,A11,Mouvements!$F:$F,"Correction +")+SUMIFS(Mouvements!$I:$I,Mouvements!$B:$B,A11,Mouvements!$F:$F,"Correction -") -> 0 | J11: =IF(A11="","",F11-G11+H11+I11) | K11: =Articles!G11 | L11: =IF(A11="","",J11-K11) | M11: =IF(A11="","",IF(J11<0,"Stock négatif",IF(J11<K11,"À commander","OK"))) | N11: =IF(A11="","",J11*Articles!H11)
A12: =Articles!A12 | B12: =Articles!B12 | C12: =Articles!C12 | D12: =Articles!D12 | E12: =Articles!E12 | F12: =Articles!F12 | G12: =SUMIFS(Mouvements!$G:$G,Mouvements!$B:$B,A12,Mouvements!$F:$F,"Départ") -> 0 | H12: =SUMIFS(Mouvements!$G:$G,Mouvements!$B:$B,A12,Mouvements!$F:$F,"Retour") -> 0 | I12: =SUMIFS(Mouvements!$I:$I,Mouvements!$B:$B,A12,Mouvements!$F:$F,"Entrée stock")+SUMIFS(Mouvements!$I:$I,Mouvements!$B:$B,A12,Mouvements!$F:$F,"Correction +")+SUMIFS(Mouvements!$I:$I,Mouvements!$B:$B,A12,Mouvements!$F:$F,"Correction -") -> 0 | J12: =IF(A12="","",F12-G12+H12+I12) | K12: =Articles!G12 | L12: =IF(A12="","",J12-K12) | M12: =IF(A12="","",IF(J12<0,"Stock négatif",IF(J12<K12,"À commander","OK"))) | N12: =IF(A12="","",J12*Articles!H12)
A13: =Articles!A13 | B13: =Articles!B13 | C13: =Articles!C13 | D13: =Articles!D13 | E13: =Articles!E13 | F13: =Articles!F13 | G13: =SUMIFS(Mouvements!$G:$G,Mouvements!$B:$B,A13,Mouvements!$F:$F,"Départ") -> 0 | H13: =SUMIFS(Mouvements!$G:$G,Mouvements!$B:$B,A13,Mouvements!$F:$F,"Retour") -> 0 | I13: =SUMIFS(Mouvements!$I:$I,Mouvements!$B:$B,A13,Mouvements!$F:$F,"Entrée stock")+SUMIFS(Mouvements!$I:$I,Mouvements!$B:$B,A13,Mouvements!$F:$F,"Correction +")+SUMIFS(Mouvements!$I:$I,Mouvements!$B:$B,A13,Mouvements!$F:$F,"Correction -") -> 0 | J13: =IF(A13="","",F13-G13+H13+I13) | K13: =Articles!G13 | L13: =IF(A13="","",J13-K13) | M13: =IF(A13="","",IF(J13<0,"Stock négatif",IF(J13<K13,"À commander","OK"))) | N13: =IF(A13="","",J13*Articles!H13)
A14: =Articles!A14 | B14: =Articles!B14 | C14: =Articles!C14 | D14: =Articles!D14 | E14: =Articles!E14 | F14: =Articles!F14 | G14: =SUMIFS(Mouvements!$G:$G,Mouvements!$B:$B,A14,Mouvements!$F:$F,"Départ") -> 0 | H14: =SUMIFS(Mouvements!$G:$G,Mouvements!$B:$B,A14,Mouvements!$F:$F,"Retour") -> 0 | I14: =SUMIFS(Mouvements!$I:$I,Mouvements!$B:$B,A14,Mouvements!$F:$F,"Entrée stock")+SUMIFS(Mouvements!$I:$I,Mouvements!$B:$B,A14,Mouvements!$F:$F,"Correction +")+SUMIFS(Mouvements!$I:$I,Mouvements!$B:$B,A14,Mouvements!$F:$F,"Correction -") -> 0 | J14: =IF(A14="","",F14-G14+H14+I14) | K14: =Articles!G14 | L14: =IF(A14="","",J14-K14) | M14: =IF(A14="","",IF(J14<0,"Stock négatif",IF(J14<K14,"À commander","OK"))) | N14: =IF(A14="","",J14*Articles!H14)
A15: =Articles!A15 | B15: =Articles!B15 | C15: =Articles!C15 | D15: =Articles!D15 | E15: =Articles!E15 | F15: =Articles!F15 | G15: =SUMIFS(Mouvements!$G:$G,Mouvements!$B:$B,A15,Mouvements!$F:$F,"Départ") -> 0 | H15: =SUMIFS(Mouvements!$G:$G,Mouvements!$B:$B,A15,Mouvements!$F:$F,"Retour") -> 0 | I15: =SUMIFS(Mouvements!$I:$I,Mouvements!$B:$B,A15,Mouvements!$F:$F,"Entrée stock")+SUMIFS(Mouvements!$I:$I,Mouvements!$B:$B,A15,Mouvements!$F:$F,"Correction +")+SUMIFS(Mouvements!$I:$I,Mouvements!$B:$B,A15,Mouvements!$F:$F,"Correction -") -> 0 | J15: =IF(A15="","",F15-G15+H15+I15) | K15: =Articles!G15 | L15: =IF(A15="","",J15-K15) | M15: =IF(A15="","",IF(J15<0,"Stock négatif",IF(J15<K15,"À commander","OK"))) | N15: =IF(A15="","",J15*Articles!H15)
A16: =Articles!A16 | B16: =Articles!B16 | C16: =Articles!C16 | D16: =Articles!D16 | E16: =Articles!E16 | F16: =Articles!F16 | G16: =SUMIFS(Mouvements!$G:$G,Mouvements!$B:$B,A16,Mouvements!$F:$F,"Départ") -> 0 | H16: =SUMIFS(Mouvements!$G:$G,Mouvements!$B:$B,A16,Mouvements!$F:$F,"Retour") -> 0 | I16: =SUMIFS(Mouvements!$I:$I,Mouvements!$B:$B,A16,Mouvements!$F:$F,"Entrée stock")+SUMIFS(Mouvements!$I:$I,Mouvements!$B:$B,A16,Mouvements!$F:$F,"Correction +")+SUMIFS(Mouvements!$I:$I,Mouvements!$B:$B,A16,Mouvements!$F:$F,"Correction -") -> 0 | J16: =IF(A16="","",F16-G16+H16+I16) | K16: =Articles!G16 | L16: =IF(A16="","",J16-K16) | M16: =IF(A16="","",IF(J16<0,"Stock négatif",IF(J16<K16,"À commander","OK"))) | N16: =IF(A16="","",J16*Articles!H16)
... A204: =Articles!A204 | B204: =Articles!B204 | C204: =Articles!C204 | D204: =Articles!D204 | E204: =Articles!E204 | F204: =Articles!F204 | G204: =SUMIFS(Mouvements!$G:$G,Mouvements!$B:$B,A204,Mouvements!$F:$F,"Départ") -> 0 | H204: =SUMIFS(Mouvements!$G:$G,Mouvements!$B:$B,A204,Mouvements!$F:$F,"Retour") -> 0 | I204: =SUMIFS(Mouvements!$I:$I,Mouvements!$B:$B,A204,Mouvements!$F:$F,"Entrée stock")+SUMIFS(Mouvements!$I:$I,Mouvements!$B:$B,A204,Mouvements!$F:$F,"Correction +")+SUMIFS(Mouvements!$I:$I,Mouvements!$B:$B,A204,Mouvements!$F:$F,"Correction -") -> 0 | J204: =IF(A204="","",F204-G204+H204+I204) | K204: =Articles!G204 | L204: =IF(A204="","",J204-K204) | M204: =IF(A204="","",IF(J204<0,"Stock négatif",IF(J204<K204,"À commander","OK"))) | N204: =IF(A204="","",J204*Articles!H204)

Sheet Synthèse Chantiers
A1: Synthèse automatique par chantier
A4: Chantier | B4: Référence | C4: Désignation | D4: Départs | E4: Retours | F4: Stock chantier | G4: Valeur sortie | H4: Dernier mouvement | I4: Statut | J4: Commentaire
A5: ='Paramètres'!D4 -> Chantier A | B5: =Articles!A5 -> VIS-6X60 | C5: =Articles!B5 -> Vis béton 6x60 | D5: =IF(OR($A5="",$B5=""),"",SUMIFS(Mouvements!$G:$G,Mouvements!$E:$E,$A5,Mouvements!$B:$B,$B5,Mouvements!$F:$F,"Départ")) -> 0 | E5: =IF(OR($A5="",$B5=""),"",SUMIFS(Mouvements!$G:$G,Mouvements!$E:$E,$A5,Mouvements!$B:$B,$B5,Mouvements!$F:$F,"Retour")) -> 0 | F5: =IF(OR($A5="",$B5=""),"",D5-E5) -> 0 | G5: =IF($B5="","",D5*VLOOKUP($B5,Articles!$A$5:$K$204,8,FALSE)) -> 0 | I5: =IF(F5="","",IF(F5>0,"Sur chantier","Soldé")) -> Soldé
A6: ='Paramètres'!D4 -> Chantier A | B6: =Articles!A6 -> PERF-001 | C6: =Articles!B6 -> Perforateur SDS | D6: =IF(OR($A6="",$B6=""),"",SUMIFS(Mouvements!$G:$G,Mouvements!$E:$E,$A6,Mouvements!$B:$B,$B6,Mouvements!$F:$F,"Départ")) -> 0 | E6: =IF(OR($A6="",$B6=""),"",SUMIFS(Mouvements!$G:$G,Mouvements!$E:$E,$A6,Mouvements!$B:$B,$B6,Mouvements!$F:$F,"Retour")) -> 0 | F6: =IF(OR($A6="",$B6=""),"",D6-E6) -> 0 | G6: =IF($B6="","",D6*VLOOKUP($B6,Articles!$A$5:$K$204,8,FALSE)) -> 0 | I6: =IF(F6="","",IF(F6>0,"Sur chantier","Soldé")) -> Soldé
A7: ='Paramètres'!D4 -> Chantier A | B7: =Articles!A7 -> GANT-L | C7: =Articles!B7 -> Gants taille L | D7: =IF(OR($A7="",$B7=""),"",SUMIFS(Mouvements!$G:$G,Mouvements!$E:$E,$A7,Mouvements!$B:$B,$B7,Mouvements!$F:$F,"Départ")) -> 0 | E7: =IF(OR($A7="",$B7=""),"",SUMIFS(Mouvements!$G:$G,Mouvements!$E:$E,$A7,Mouvements!$B:$B,$B7,Mouvements!$F:$F,"Retour")) -> 0 | F7: =IF(OR($A7="",$B7=""),"",D7-E7) -> 0 | G7: =IF($B7="","",D7*VLOOKUP($B7,Articles!$A$5:$K$204,8,FALSE)) -> 0 | I7: =IF(F7="","",IF(F7>0,"Sur chantier","Soldé")) -> Soldé
A8: ='Paramètres'!D4 -> Chantier A | B8: =Articles!A8 -> 12345 | C8: =Articles!B8 -> Quentin | D8: =IF(OR($A8="",$B8=""),"",SUMIFS(Mouvements!$G:$G,Mouvements!$E:$E,$A8,Mouvements!$B:$B,$B8,Mouvements!$F:$F,"Départ")) -> 100 | E8: =IF(OR($A8="",$B8=""),"",SUMIFS(Mouvements!$G:$G,Mouvements!$E:$E,$A8,Mouvements!$B:$B,$B8,Mouvements!$F:$F,"Retour")) -> 0 | F8: =IF(OR($A8="",$B8=""),"",D8-E8) -> 100 | G8: =IF($B8="","",D8*VLOOKUP($B8,Articles!$A$5:$K$204,8,FALSE)) -> 1000 | I8: =IF(F8="","",IF(F8>0,"Sur chantier","Soldé")) -> Sur chantier
A9: ='Paramètres'!D4 -> Chantier A | B9: =Articles!A9 -> 4969272 | C9: =Articles!B9 -> teben | D9: =IF(OR($A9="",$B9=""),"",SUMIFS(Mouvements!$G:$G,Mouvements!$E:$E,$A9,Mouvements!$B:$B,$B9,Mouvements!$F:$F,"Départ")) -> 4 | E9: =IF(OR($A9="",$B9=""),"",SUMIFS(Mouvements!$G:$G,Mouvements!$E:$E,$A9,Mouvements!$B:$B,$B9,Mouvements!$F:$F,"Retour")) -> 0 | F9: =IF(OR($A9="",$B9=""),"",D9-E9) -> 4 | G9: =IF($B9="","",D9*VLOOKUP($B9,Articles!$A$5:$K$204,8,FALSE)) -> 220 | I9: =IF(F9="","",IF(F9>0,"Sur chantier","Soldé")) -> Sur chantier
A10: ='Paramètres'!D4 -> Chantier A | B10: =Articles!A10 | C10: =Articles!B10 | D10: =IF(OR($A10="",$B10=""),"",SUMIFS(Mouvements!$G:$G,Mouvements!$E:$E,$A10,Mouvements!$B:$B,$B10,Mouvements!$F:$F,"Départ")) | E10: =IF(OR($A10="",$B10=""),"",SUMIFS(Mouvements!$G:$G,Mouvements!$E:$E,$A10,Mouvements!$B:$B,$B10,Mouvements!$F:$F,"Retour")) | F10: =IF(OR($A10="",$B10=""),"",D10-E10) | G10: =IF($B10="","",D10*VLOOKUP($B10,Articles!$A$5:$K$204,8,FALSE)) | I10: =IF(F10="","",IF(F10>0,"Sur chantier","Soldé"))
A11: ='Paramètres'!D4 -> Chantier A | B11: =Articles!A11 | C11: =Articles!B11 | D11: =IF(OR($A11="",$B11=""),"",SUMIFS(Mouvements!$G:$G,Mouvements!$E:$E,$A11,Mouvements!$B:$B,$B11,Mouvements!$F:$F,"Départ")) | E11: =IF(OR($A11="",$B11=""),"",SUMIFS(Mouvements!$G:$G,Mouvements!$E:$E,$A11,Mouvements!$B:$B,$B11,Mouvements!$F:$F,"Retour")) | F11: =IF(OR($A11="",$B11=""),"",D11-E11) | G11: =IF($B11="","",D11*VLOOKUP($B11,Articles!$A$5:$K$204,8,FALSE)) | I11: =IF(F11="","",IF(F11>0,"Sur chantier","Soldé"))
A12: ='Paramètres'!D4 -> Chantier A | B12: =Articles!A12 | C12: =Articles!B12 | D12: =IF(OR($A12="",$B12=""),"",SUMIFS(Mouvements!$G:$G,Mouvements!$E:$E,$A12,Mouvements!$B:$B,$B12,Mouvements!$F:$F,"Départ")) | E12: =IF(OR($A12="",$B12=""),"",SUMIFS(Mouvements!$G:$G,Mouvements!$E:$E,$A12,Mouvements!$B:$B,$B12,Mouvements!$F:$F,"Retour")) | F12: =IF(OR($A12="",$B12=""),"",D12-E12) | G12: =IF($B12="","",D12*VLOOKUP($B12,Articles!$A$5:$K$204,8,FALSE)) | I12: =IF(F12="","",IF(F12>0,"Sur chantier","Soldé"))
A13: ='Paramètres'!D4 -> Chantier A | B13: =Articles!A13 | C13: =Articles!B13 | D13: =IF(OR($A13="",$B13=""),"",SUMIFS(Mouvements!$G:$G,Mouvements!$E:$E,$A13,Mouvements!$B:$B,$B13,Mouvements!$F:$F,"Départ")) | E13: =IF(OR($A13="",$B13=""),"",SUMIFS(Mouvements!$G:$G,Mouvements!$E:$E,$A13,Mouvements!$B:$B,$B13,Mouvements!$F:$F,"Retour")) | F13: =IF(OR($A13="",$B13=""),"",D13-E13) | G13: =IF($B13="","",D13*VLOOKUP($B13,Articles!$A$5:$K$204,8,FALSE)) | I13: =IF(F13="","",IF(F13>0,"Sur chantier","Soldé"))
A14: ='Paramètres'!D4 -> Chantier A | B14: =Articles!A14 | C14: =Articles!B14 | D14: =IF(OR($A14="",$B14=""),"",SUMIFS(Mouvements!$G:$G,Mouvements!$E:$E,$A14,Mouvements!$B:$B,$B14,Mouvements!$F:$F,"Départ")) | E14: =IF(OR($A14="",$B14=""),"",SUMIFS(Mouvements!$G:$G,Mouvements!$E:$E,$A14,Mouvements!$B:$B,$B14,Mouvements!$F:$F,"Retour")) | F14: =IF(OR($A14="",$B14=""),"",D14-E14) | G14: =IF($B14="","",D14*VLOOKUP($B14,Articles!$A$5:$K$204,8,FALSE)) | I14: =IF(F14="","",IF(F14>0,"Sur chantier","Soldé"))
A15: ='Paramètres'!D4 -> Chantier A | B15: =Articles!A15 | C15: =Articles!B15 | D15: =IF(OR($A15="",$B15=""),"",SUMIFS(Mouvements!$G:$G,Mouvements!$E:$E,$A15,Mouvements!$B:$B,$B15,Mouvements!$F:$F,"Départ")) | E15: =IF(OR($A15="",$B15=""),"",SUMIFS(Mouvements!$G:$G,Mouvements!$E:$E,$A15,Mouvements!$B:$B,$B15,Mouvements!$F:$F,"Retour")) | F15: =IF(OR($A15="",$B15=""),"",D15-E15) | G15: =IF($B15="","",D15*VLOOKUP($B15,Articles!$A$5:$K$204,8,FALSE)) | I15: =IF(F15="","",IF(F15>0,"Sur chantier","Soldé"))
A16: ='Paramètres'!D4 -> Chantier A | B16: =Articles!A16 | C16: =Articles!B16 | D16: =IF(OR($A16="",$B16=""),"",SUMIFS(Mouvements!$G:$G,Mouvements!$E:$E,$A16,Mouvements!$B:$B,$B16,Mouvements!$F:$F,"Départ")) | E16: =IF(OR($A16="",$B16=""),"",SUMIFS(Mouvements!$G:$G,Mouvements!$E:$E,$A16,Mouvements!$B:$B,$B16,Mouvements!$F:$F,"Retour")) | F16: =IF(OR($A16="",$B16=""),"",D16-E16) | G16: =IF($B16="","",D16*VLOOKUP($B16,Articles!$A$5:$K$204,8,FALSE)) | I16: =IF(F16="","",IF(F16>0,"Sur chantier","Soldé"))
A17: ='Paramètres'!D4 -> Chantier A | B17: =Articles!A17 | C17: =Articles!B17 | D17: =IF(OR($A17="",$B17=""),"",SUMIFS(Mouvements!$G:$G,Mouvements!$E:$E,$A17,Mouvements!$B:$B,$B17,Mouvements!$F:$F,"Départ")) | E17: =IF(OR($A17="",$B17=""),"",SUMIFS(Mouvements!$G:$G,Mouvements!$E:$E,$A17,Mouvements!$B:$B,$B17,Mouvements!$F:$F,"Retour")) | F17: =IF(OR($A17="",$B17=""),"",D17-E17) | G17: =IF($B17="","",D17*VLOOKUP($B17,Articles!$A$5:$K$204,8,FALSE)) | I17: =IF(F17="","",IF(F17>0,"Sur chantier","Soldé"))
A18: ='Paramètres'!D4 -> Chantier A | B18: =Articles!A18 | C18: =Articles!B18 | D18: =IF(OR($A18="",$B18=""),"",SUMIFS(Mouvements!$G:$G,Mouvements!$E:$E,$A18,Mouvements!$B:$B,$B18,Mouvements!$F:$F,"Départ")) | E18: =IF(OR($A18="",$B18=""),"",SUMIFS(Mouvements!$G:$G,Mouvements!$E:$E,$A18,Mouvements!$B:$B,$B18,Mouvements!$F:$F,"Retour")) | F18: =IF(OR($A18="",$B18=""),"",D18-E18) | G18: =IF($B18="","",D18*VLOOKUP($B18,Articles!$A$5:$K$204,8,FALSE)) | I18: =IF(F18="","",IF(F18>0,"Sur chantier","Soldé"))
A19: ='Paramètres'!D4 -> Chantier A | B19: =Articles!A19 | C19: =Articles!B19 | D19: =IF(OR($A19="",$B19=""),"",SUMIFS(Mouvements!$G:$G,Mouvements!$E:$E,$A19,Mouvements!$B:$B,$B19,Mouvements!$F:$F,"Départ")) | E19: =IF(OR($A19="",$B19=""),"",SUMIFS(Mouvements!$G:$G,Mouvements!$E:$E,$A19,Mouvements!$B:$B,$B19,Mouvements!$F:$F,"Retour")) | F19: =IF(OR($A19="",$B19=""),"",D19-E19) | G19: =IF($B19="","",D19*VLOOKUP($B19,Articles!$A$5:$K$204,8,FALSE)) | I19: =IF(F19="","",IF(F19>0,"Sur chantier","Soldé"))
A20: ='Paramètres'!D4 -> Chantier A | B20: =Articles!A20 | C20: =Articles!B20 | D20: =IF(OR($A20="",$B20=""),"",SUMIFS(Mouvements!$G:$G,Mouvements!$E:$E,$A20,Mouvements!$B:$B,$B20,Mouvements!$F:$F,"Départ")) | E20: =IF(OR($A20="",$B20=""),"",SUMIFS(Mouvements!$G:$G,Mouvements!$E:$E,$A20,Mouvements!$B:$B,$B20,Mouvements!$F:$F,"Retour")) | F20: =IF(OR($A20="",$B20=""),"",D20-E20) | G20: =IF($B20="","",D20*VLOOKUP($B20,Articles!$A$5:$K$204,8,FALSE)) | I20: =IF(F20="","",IF(F20>0,"Sur chantier","Soldé"))
A21: ='Paramètres'!D4 -> Chantier A | B21: =Articles!A21 | C21: =Articles!B21 | D21: =IF(OR($A21="",$B21=""),"",SUMIFS(Mouvements!$G:$G,Mouvements!$E:$E,$A21,Mouvements!$B:$B,$B21,Mouvements!$F:$F,"Départ")) | E21: =IF(OR($A21="",$B21=""),"",SUMIFS(Mouvements!$G:$G,Mouvements!$E:$E,$A21,Mouvements!$B:$B,$B21,Mouvements!$F:$F,"Retour")) | F21: =IF(OR($A21="",$B21=""),"",D21-E21) | G21: =IF($B21="","",D21*VLOOKUP($B21,Articles!$A$5:$K$204,8,FALSE)) | I21: =IF(F21="","",IF(F21>0,"Sur chantier","Soldé"))
A22: ='Paramètres'!D4 -> Chantier A | B22: =Articles!A22 | C22: =Articles!B22 | D22: =IF(OR($A22="",$B22=""),"",SUMIFS(Mouvements!$G:$G,Mouvements!$E:$E,$A22,Mouvements!$B:$B,$B22,Mouvements!$F:$F,"Départ")) | E22: =IF(OR($A22="",$B22=""),"",SUMIFS(Mouvements!$G:$G,Mouvements!$E:$E,$A22,Mouvements!$B:$B,$B22,Mouvements!$F:$F,"Retour")) | F22: =IF(OR($A22="",$B22=""),"",D22-E22) | G22: =IF($B22="","",D22*VLOOKUP($B22,Articles!$A$5:$K$204,8,FALSE)) | I22: =IF(F22="","",IF(F22>0,"Sur chantier","Soldé"))
A23: ='Paramètres'!D4 -> Chantier A | B23: =Articles!A23 | C23: =Articles!B23 | D23: =IF(OR($A23="",$B23=""),"",SUMIFS(Mouvements!$G:$G,Mouvements!$E:$E,$A23,Mouvements!$B:$B,$B23,Mouvements!$F:$F,"Départ")) | E23: =IF(OR($A23="",$B23=""),"",SUMIFS(Mouvements!$G:$G,Mouvements!$E:$E,$A23,Mouvements!$B:$B,$B23,Mouvements!$F:$F,"Retour")) | F23: =IF(OR($A23="",$B23=""),"",D23-E23) | G23: =IF($B23="","",D23*VLOOKUP($B23,Articles!$A$5:$K$204,8,FALSE)) | I23: =IF(F23="","",IF(F23>0,"Sur chantier","Soldé"))
A24: ='Paramètres'!D4 -> Chantier A | B24: =Articles!A24 | C24: =Articles!B24 | D24: =IF(OR($A24="",$B24=""),"",SUMIFS(Mouvements!$G:$G,Mouvements!$E:$E,$A24,Mouvements!$B:$B,$B24,Mouvements!$F:$F,"Départ")) | E24: =IF(OR($A24="",$B24=""),"",SUMIFS(Mouvements!$G:$G,Mouvements!$E:$E,$A24,Mouvements!$B:$B,$B24,Mouvements!$F:$F,"Retour")) | F24: =IF(OR($A24="",$B24=""),"",D24-E24) | G24: =IF($B24="","",D24*VLOOKUP($B24,Articles!$A$5:$K$204,8,FALSE)) | I24: =IF(F24="","",IF(F24>0,"Sur chantier","Soldé"))
A25: ='Paramètres'!D4 -> Chantier A | B25: =Articles!A25 | C25: =Articles!B25 | D25: =IF(OR($A25="",$B25=""),"",SUMIFS(Mouvements!$G:$G,Mouvements!$E:$E,$A25,Mouvements!$B:$B,$B25,Mouvements!$F:$F,"Départ")) | E25: =IF(OR($A25="",$B25=""),"",SUMIFS(Mouvements!$G:$G,Mouvements!$E:$E,$A25,Mouvements!$B:$B,$B25,Mouvements!$F:$F,"Retour")) | F25: =IF(OR($A25="",$B25=""),"",D25-E25) | G25: =IF($B25="","",D25*VLOOKUP($B25,Articles!$A$5:$K$204,8,FALSE)) | I25: =IF(F25="","",IF(F25>0,"Sur chantier","Soldé"))
A26: ='Paramètres'!D4 -> Chantier A | B26: =Articles!A26 | C26: =Articles!B26 | D26: =IF(OR($A26="",$B26=""),"",SUMIFS(Mouvements!$G:$G,Mouvements!$E:$E,$A26,Mouvements!$B:$B,$B26,Mouvements!$F:$F,"Départ")) | E26: =IF(OR($A26="",$B26=""),"",SUMIFS(Mouvements!$G:$G,Mouvements!$E:$E,$A26,Mouvements!$B:$B,$B26,Mouvements!$F:$F,"Retour")) | F26: =IF(OR($A26="",$B26=""),"",D26-E26) | G26: =IF($B26="","",D26*VLOOKUP($B26,Articles!$A$5:$K$204,8,FALSE)) | I26: =IF(F26="","",IF(F26>0,"Sur chantier","Soldé"))
A27: ='Paramètres'!D4 -> Chantier A | B27: =Articles!A27 | C27: =Articles!B27 | D27: =IF(OR($A27="",$B27=""),"",SUMIFS(Mouvements!$G:$G,Mouvements!$E:$E,$A27,Mouvements!$B:$B,$B27,Mouvements!$F:$F,"Départ")) | E27: =IF(OR($A27="",$B27=""),"",SUMIFS(Mouvements!$G:$G,Mouvements!$E:$E,$A27,Mouvements!$B:$B,$B27,Mouvements!$F:$F,"Retour")) | F27: =IF(OR($A27="",$B27=""),"",D27-E27) | G27: =IF($B27="","",D27*VLOOKUP($B27,Articles!$A$5:$K$204,8,FALSE)) | I27: =IF(F27="","",IF(F27>0,"Sur chantier","Soldé"))
A28: ='Paramètres'!D4 -> Chantier A | B28: =Articles!A28 | C28: =Articles!B28 | D28: =IF(OR($A28="",$B28=""),"",SUMIFS(Mouvements!$G:$G,Mouvements!$E:$E,$A28,Mouvements!$B:$B,$B28,Mouvements!$F:$F,"Départ")) | E28: =IF(OR($A28="",$B28=""),"",SUMIFS(Mouvements!$G:$G,Mouvements!$E:$E,$A28,Mouvements!$B:$B,$B28,Mouvements!$F:$F,"Retour")) | F28: =IF(OR($A28="",$B28=""),"",D28-E28) | G28: =IF($B28="","",D28*VLOOKUP($B28,Articles!$A$5:$K$204,8,FALSE)) | I28: =IF(F28="","",IF(F28>0,"Sur chantier","Soldé"))
A29: ='Paramètres'!D4 -> Chantier A | B29: =Articles!A29 | C29: =Articles!B29 | D29: =IF(OR($A29="",$B29=""),"",SUMIFS(Mouvements!$G:$G,Mouvements!$E:$E,$A29,Mouvements!$B:$B,$B29,Mouvements!$F:$F,"Départ")) | E29: =IF(OR($A29="",$B29=""),"",SUMIFS(Mouvements!$G:$G,Mouvements!$E:$E,$A29,Mouvements!$B:$B,$B29,Mouvements!$F:$F,"Retour")) | F29: =IF(OR($A29="",$B29=""),"",D29-E29) | G29: =IF($B29="","",D29*VLOOKUP($B29,Articles!$A$5:$K$204,8,FALSE)) | I29: =IF(F29="","",IF(F29>0,"Sur chantier","Soldé"))
A30: ='Paramètres'!D4 -> Chantier A | B30: =Articles!A30 | C30: =Articles!B30 | D30: =IF(OR($A30="",$B30=""),"",SUMIFS(Mouvements!$G:$G,Mouvements!$E:$E,$A30,Mouvements!$B:$B,$B30,Mouvements!$F:$F,"Départ")) | E30: =IF(OR($A30="",$B30=""),"",SUMIFS(Mouvements!$G:$G,Mouvements!$E:$E,$A30,Mouvements!$B:$B,$B30,Mouvements!$F:$F,"Retour")) | F30: =IF(OR($A30="",$B30=""),"",D30-E30) | G30: =IF($B30="","",D30*VLOOKUP($B30,Articles!$A$5:$K$204,8,FALSE)) | I30: =IF(F30="","",IF(F30>0,"Sur chantier","Soldé"))
A31: ='Paramètres'!D4 -> Chantier A | B31: =Articles!A31 | C31: =Articles!B31 | D31: =IF(OR($A31="",$B31=""),"",SUMIFS(Mouvements!$G:$G,Mouvements!$E:$E,$A31,Mouvements!$B:$B,$B31,Mouvements!$F:$F,"Départ")) | E31: =IF(OR($A31="",$B31=""),"",SUMIFS(Mouvements!$G:$G,Mouvements!$E:$E,$A31,Mouvements!$B:$B,$B31,Mouvements!$F:$F,"Retour")) | F31: =IF(OR($A31="",$B31=""),"",D31-E31) | G31: =IF($B31="","",D31*VLOOKUP($B31,Articles!$A$5:$K$204,8,FALSE)) | I31: =IF(F31="","",IF(F31>0,"Sur chantier","Soldé"))
A32: ='Paramètres'!D4 -> Chantier A | B32: =Articles!A32 | C32: =Articles!B32 | D32: =IF(OR($A32="",$B32=""),"",SUMIFS(Mouvements!$G:$G,Mouvements!$E:$E,$A32,Mouvements!$B:$B,$B32,Mouvements!$F:$F,"Départ")) | E32: =IF(OR($A32="",$B32=""),"",SUMIFS(Mouvements!$G:$G,Mouvements!$E:$E,$A32,Mouvements!$B:$B,$B32,Mouvements!$F:$F,"Retour")) | F32: =IF(OR($A32="",$B32=""),"",D32-E32) | G32: =IF($B32="","",D32*VLOOKUP($B32,Articles!$A$5:$K$204,8,FALSE)) | I32: =IF(F32="","",IF(F32>0,"Sur chantier","Soldé"))
A33: ='Paramètres'!D4 -> Chantier A | B33: =Articles!A33 | C33: =Articles!B33 | D33: =IF(OR($A33="",$B33=""),"",SUMIFS(Mouvements!$G:$G,Mouvements!$E:$E,$A33,Mouvements!$B:$B,$B33,Mouvements!$F:$F,"Départ")) | E33: =IF(OR($A33="",$B33=""),"",SUMIFS(Mouvements!$G:$G,Mouvements!$E:$E,$A33,Mouvements!$B:$B,$B33,Mouvements!$F:$F,"Retour")) | F33: =IF(OR($A33="",$B33=""),"",D33-E33) | G33: =IF($B33="","",D33*VLOOKUP($B33,Articles!$A$5:$K$204,8,FALSE)) | I33: =IF(F33="","",IF(F33>0,"Sur chantier","Soldé"))
A34: ='Paramètres'!D4 -> Chantier A | B34: =Articles!A34 | C34: =Articles!B34 | D34: =IF(OR($A34="",$B34=""),"",SUMIFS(Mouvements!$G:$G,Mouvements!$E:$E,$A34,Mouvements!$B:$B,$B34,Mouvements!$F:$F,"Départ")) | E34: =IF(OR($A34="",$B34=""),"",SUMIFS(Mouvements!$G:$G,Mouvements!$E:$E,$A34,Mouvements!$B:$B,$B34,Mouvements!$F:$F,"Retour")) | F34: =IF(OR($A34="",$B34=""),"",D34-E34) | G34: =IF($B34="","",D34*VLOOKUP($B34,Articles!$A$5:$K$204,8,FALSE)) | I34: =IF(F34="","",IF(F34>0,"Sur chantier","Soldé"))
A35: ='Paramètres'!D5 -> Chantier B | B35: =Articles!A5 -> VIS-6X60 | C35: =Articles!B5 -> Vis béton 6x60 | D35: =IF(OR($A35="",$B35=""),"",SUMIFS(Mouvements!$G:$G,Mouvements!$E:$E,$A35,Mouvements!$B:$B,$B35,Mouvements!$F:$F,"Départ")) -> 0 | E35: =IF(OR($A35="",$B35=""),"",SUMIFS(Mouvements!$G:$G,Mouvements!$E:$E,$A35,Mouvements!$B:$B,$B35,Mouvements!$F:$F,"Retour")) -> 0 | F35: =IF(OR($A35="",$B35=""),"",D35-E35) -> 0 | G35: =IF($B35="","",D35*VLOOKUP($B35,Articles!$A$5:$K$204,8,FALSE)) -> 0 | I35: =IF(F35="","",IF(F35>0,"Sur chantier","Soldé")) -> Soldé
A36: ='Paramètres'!D5 -> Chantier B | B36: =Articles!A6 -> PERF-001 | C36: =Articles!B6 -> Perforateur SDS | D36: =IF(OR($A36="",$B36=""),"",SUMIFS(Mouvements!$G:$G,Mouvements!$E:$E,$A36,Mouvements!$B:$B,$B36,Mouvements!$F:$F,"Départ")) -> 0 | E36: =IF(OR($A36="",$B36=""),"",SUMIFS(Mouvements!$G:$G,Mouvements!$E:$E,$A36,Mouvements!$B:$B,$B36,Mouvements!$F:$F,"Retour")) -> 0 | F36: =IF(OR($A36="",$B36=""),"",D36-E36) -> 0 | G36: =IF($B36="","",D36*VLOOKUP($B36,Articles!$A$5:$K$204,8,FALSE)) -> 0 | I36: =IF(F36="","",IF(F36>0,"Sur chantier","Soldé")) -> Soldé
A37: ='Paramètres'!D5 -> Chantier B | B37: =Articles!A7 -> GANT-L | C37: =Articles!B7 -> Gants taille L | D37: =IF(OR($A37="",$B37=""),"",SUMIFS(Mouvements!$G:$G,Mouvements!$E:$E,$A37,Mouvements!$B:$B,$B37,Mouvements!$F:$F,"Départ")) -> 0 | E37: =IF(OR($A37="",$B37=""),"",SUMIFS(Mouvements!$G:$G,Mouvements!$E:$E,$A37,Mouvements!$B:$B,$B37,Mouvements!$F:$F,"Retour")) -> 0 | F37: =IF(OR($A37="",$B37=""),"",D37-E37) -> 0 | G37: =IF($B37="","",D37*VLOOKUP($B37,Articles!$A$5:$K$204,8,FALSE)) -> 0 | I37: =IF(F37="","",IF(F37>0,"Sur chantier","Soldé")) -> Soldé
A38: ='Paramètres'!D5 -> Chantier B | B38: =Articles!A8 -> 12345 | C38: =Articles!B8 -> Quentin | D38: =IF(OR($A38="",$B38=""),"",SUMIFS(Mouvements!$G:$G,Mouvements!$E:$E,$A38,Mouvements!$B:$B,$B38,Mouvements!$F:$F,"Départ")) -> 0 | E38: =IF(OR($A38="",$B38=""),"",SUMIFS(Mouvements!$G:$G,Mouvements!$E:$E,$A38,Mouvements!$B:$B,$B38,Mouvements!$F:$F,"Retour")) -> 0 | F38: =IF(OR($A38="",$B38=""),"",D38-E38) -> 0 | G38: =IF($B38="","",D38*VLOOKUP($B38,Articles!$A$5:$K$204,8,FALSE)) -> 0 | I38: =IF(F38="","",IF(F38>0,"Sur chantier","Soldé")) -> Soldé
A39: ='Paramètres'!D5 -> Chantier B | B39: =Articles!A9 -> 4969272 | C39: =Articles!B9 -> teben | D39: =IF(OR($A39="",$B39=""),"",SUMIFS(Mouvements!$G:$G,Mouvements!$E:$E,$A39,Mouvements!$B:$B,$B39,Mouvements!$F:$F,"Départ")) -> 0 | E39: =IF(OR($A39="",$B39=""),"",SUMIFS(Mouvements!$G:$G,Mouvements!$E:$E,$A39,Mouvements!$B:$B,$B39,Mouvements!$F:$F,"Retour")) -> 0 | F39: =IF(OR($A39="",$B39=""),"",D39-E39) -> 0 | G39: =IF($B39="","",D39*VLOOKUP($B39,Articles!$A$5:$K$204,8,FALSE)) -> 0 | I39: =IF(F39="","",IF(F39>0,"Sur chantier","Soldé")) -> Soldé
A40: ='Paramètres'!D5 -> Chantier B | B40: =Articles!A10 | C40: =Articles!B10 | D40: =IF(OR($A40="",$B40=""),"",SUMIFS(Mouvements!$G:$G,Mouvements!$E:$E,$A40,Mouvements!$B:$B,$B40,Mouvements!$F:$F,"Départ")) | E40: =IF(OR($A40="",$B40=""),"",SUMIFS(Mouvements!$G:$G,Mouvements!$E:$E,$A40,Mouvements!$B:$B,$B40,Mouvements!$F:$F,"Retour")) | F40: =IF(OR($A40="",$B40=""),"",D40-E40) | G40: =IF($B40="","",D40*VLOOKUP($B40,Articles!$A$5:$K$204,8,FALSE)) | I40: =IF(F40="","",IF(F40>0,"Sur chantier","Soldé"))
A41: ='Paramètres'!D5 -> Chantier B | B41: =Articles!A11 | C41: =Articles!B11 | D41: =IF(OR($A41="",$B41=""),"",SUMIFS(Mouvements!$G:$G,Mouvements!$E:$E,$A41,Mouvements!$B:$B,$B41,Mouvements!$F:$F,"Départ")) | E41: =IF(OR($A41="",$B41=""),"",SUMIFS(Mouvements!$G:$G,Mouvements!$E:$E,$A41,Mouvements!$B:$B,$B41,Mouvements!$F:$F,"Retour")) | F41: =IF(OR($A41="",$B41=""),"",D41-E41) | G41: =IF($B41="","",D41*VLOOKUP($B41,Articles!$A$5:$K$204,8,FALSE)) | I41: =IF(F41="","",IF(F41>0,"Sur chantier","Soldé"))
A42: ='Paramètres'!D5 -> Chantier B | B42: =Articles!A12 | C42: =Articles!B12 | D42: =IF(OR($A42="",$B42=""),"",SUMIFS(Mouvements!$G:$G,Mouvements!$E:$E,$A42,Mouvements!$B:$B,$B42,Mouvements!$F:$F,"Départ")) | E42: =IF(OR($A42="",$B42=""),"",SUMIFS(Mouvements!$G:$G,Mouvements!$E:$E,$A42,Mouvements!$B:$B,$B42,Mouvements!$F:$F,"Retour")) | F42: =IF(OR($A42="",$B42=""),"",D42-E42) | G42: =IF($B42="","",D42*VLOOKUP($B42,Articles!$A$5:$K$204,8,FALSE)) | I42: =IF(F42="","",IF(F42>0,"Sur chantier","Soldé"))
...

Sheet Chantier A
A1: Chantier A - suivi automatique
A2: Cette feuille se met à jour depuis Mouvements. Duplique-la pour un autre chantier et change B3.
A3: Chantier | B3: Chantier A
A5: Référence | B5: Désignation | C5: Départs | D5: Retours | E5: Reste chantier | F5: Dernière sortie | G5: Statut | H5: Observation | I5: Contrôle
A6: =Articles!A5 -> VIS-6X60 | B6: =Articles!B5 -> Vis béton 6x60 | C6: 10 | D6: =IF(A6="","",SUMIFS(Mouvements!$G:$G,Mouvements!$E:$E,$B$3,Mouvements!$B:$B,A6,Mouvements!$F:$F,"Retour")) -> 0 | E6: =IF(A6="","",C6-D6) -> 10 | G6: =IF(E6="","",IF(E6>0,"À récupérer","Soldé")) -> À récupérer | I6: =IF(E6<0,"Retour > départ","")
A7: =Articles!A6 -> PERF-001 | B7: =Articles!B6 -> Perforateur SDS | C7: =IF(A7="","",SUMIFS(Mouvements!$G:$G,Mouvements!$E:$E,$B$3,Mouvements!$B:$B,A7,Mouvements!$F:$F,"Départ")) -> 0 | D7: =IF(A7="","",SUMIFS(Mouvements!$G:$G,Mouvements!$E:$E,$B$3,Mouvements!$B:$B,A7,Mouvements!$F:$F,"Retour")) -> 0 | E7: =IF(A7="","",C7-D7) -> 0 | G7: =IF(E7="","",IF(E7>0,"À récupérer","Soldé")) -> Soldé | I7: =IF(E7<0,"Retour > départ","")
A8: =Articles!A7 -> GANT-L | B8: =Articles!B7 -> Gants taille L | C8: =IF(A8="","",SUMIFS(Mouvements!$G:$G,Mouvements!$E:$E,$B$3,Mouvements!$B:$B,A8,Mouvements!$F:$F,"Départ")) -> 0 | D8: =IF(A8="","",SUMIFS(Mouvements!$G:$G,Mouvements!$E:$E,$B$3,Mouvements!$B:$B,A8,Mouvements!$F:$F,"Retour")) -> 0 | E8: =IF(A8="","",C8-D8) -> 0 | G8: =IF(E8="","",IF(E8>0,"À récupérer","Soldé")) -> Soldé | I8: =IF(E8<0,"Retour > départ","")
A9: =Articles!A8 -> 12345 | B9: =Articles!B8 -> Quentin | C9: 10 | D9: =IF(A9="","",SUMIFS(Mouvements!$G:$G,Mouvements!$E:$E,$B$3,Mouvements!$B:$B,A9,Mouvements!$F:$F,"Retour")) -> 0 | E9: =IF(A9="","",C9-D9) -> 10 | G9: =IF(E9="","",IF(E9>0,"À récupérer","Soldé")) -> À récupérer | I9: =IF(E9<0,"Retour > départ","")
A10: =Articles!A9 -> 4969272 | B10: =Articles!B9 -> teben | C10: =IF(A10="","",SUMIFS(Mouvements!$G:$G,Mouvements!$E:$E,$B$3,Mouvements!$B:$B,A10,Mouvements!$F:$F,"Départ")) -> 4 | D10: =IF(A10="","",SUMIFS(Mouvements!$G:$G,Mouvements!$E:$E,$B$3,Mouvements!$B:$B,A10,Mouvements!$F:$F,"Retour")) -> 0 | E10: =IF(A10="","",C10-D10) -> 4 | G10: =IF(E10="","",IF(E10>0,"À récupérer","Soldé")) -> À récupérer | I10: =IF(E10<0,"Retour > départ","")
A11: =Articles!A10 | B11: =Articles!B10 | C11: =IF(A11="","",SUMIFS(Mouvements!$G:$G,Mouvements!$E:$E,$B$3,Mouvements!$B:$B,A11,Mouvements!$F:$F,"Départ")) | D11: =IF(A11="","",SUMIFS(Mouvements!$G:$G,Mouvements!$E:$E,$B$3,Mouvements!$B:$B,A11,Mouvements!$F:$F,"Retour")) | E11: =IF(A11="","",C11-D11) | G11: =IF(E11="","",IF(E11>0,"À récupérer","Soldé")) | I11: =IF(E11<0,"Retour > départ","")
A12: =Articles!A11 | B12: =Articles!B11 | C12: =IF(A12="","",SUMIFS(Mouvements!$G:$G,Mouvements!$E:$E,$B$3,Mouvements!$B:$B,A12,Mouvements!$F:$F,"Départ")) | D12: =IF(A12="","",SUMIFS(Mouvements!$G:$G,Mouvements!$E:$E,$B$3,Mouvements!$B:$B,A12,Mouvements!$F:$F,"Retour")) | E12: =IF(A12="","",C12-D12) | G12: =IF(E12="","",IF(E12>0,"À récupérer","Soldé")) | I12: =IF(E12<0,"Retour > départ","")
A13: =Articles!A12 | B13: =Articles!B12 | C13: =IF(A13="","",SUMIFS(Mouvements!$G:$G,Mouvements!$E:$E,$B$3,Mouvements!$B:$B,A13,Mouvements!$F:$F,"Départ")) | D13: =IF(A13="","",SUMIFS(Mouvements!$G:$G,Mouvements!$E:$E,$B$3,Mouvements!$B:$B,A13,Mouvements!$F:$F,"Retour")) | E13: =IF(A13="","",C13-D13) | G13: =IF(E13="","",IF(E13>0,"À récupérer","Soldé")) | I13: =IF(E13<0,"Retour > départ","")
A14: =Articles!A13 | B14: =Articles!B13 | C14: =IF(A14="","",SUMIFS(Mouvements!$G:$G,Mouvements!$E:$E,$B$3,Mouvements!$B:$B,A14,Mouvements!$F:$F,"Départ")) | D14: =IF(A14="","",SUMIFS(Mouvements!$G:$G,Mouvements!$E:$E,$B$3,Mouvements!$B:$B,A14,Mouvements!$F:$F,"Retour")) | E14: =IF(A14="","",C14-D14) | G14: =IF(E14="","",IF(E14>0,"À récupérer","Soldé")) | I14: =IF(E14<0,"Retour > départ","")
A15: =Articles!A14 | B15: =Articles!B14 | C15: =IF(A15="","",SUMIFS(Mouvements!$G:$G,Mouvements!$E:$E,$B$3,Mouvements!$B:$B,A15,Mouvements!$F:$F,"Départ")) | D15: =IF(A15="","",SUMIFS(Mouvements!$G:$G,Mouvements!$E:$E,$B$3,Mouvements!$B:$B,A15,Mouvements!$F:$F,"Retour")) | E15: =IF(A15="","",C15-D15) | G15: =IF(E15="","",IF(E15>0,"À récupérer","Soldé")) | I15: =IF(E15<0,"Retour > départ","")
A16: =Articles!A15 | B16: =Articles!B15 | C16: =IF(A16="","",SUMIFS(Mouvements!$G:$G,Mouvements!$E:$E,$B$3,Mouvements!$B:$B,A16,Mouvements!$F:$F,"Départ")) | D16: =IF(A16="","",SUMIFS(Mouvements!$G:$G,Mouvements!$E:$E,$B$3,Mouvements!$B:$B,A16,Mouvements!$F:$F,"Retour")) | E16: =IF(A16="","",C16-D16) | G16: =IF(E16="","",IF(E16>0,"À récupérer","Soldé")) | I16: =IF(E16<0,"Retour > départ","")
A17: =Articles!A16 | B17: =Articles!B16 | C17: =IF(A17="","",SUMIFS(Mouvements!$G:$G,Mouvements!$E:$E,$B$3,Mouvements!$B:$B,A17,Mouvements!$F:$F,"Départ")) | D17: =IF(A17="","",SUMIFS(Mouvements!$G:$G,Mouvements!$E:$E,$B$3,Mouvements!$B:$B,A17,Mouvements!$F:$F,"Retour")) | E17: =IF(A17="","",C17-D17) | G17: =IF(E17="","",IF(E17>0,"À récupérer","Soldé")) | I17: =IF(E17<0,"Retour > départ","")
A18: =Articles!A17 | B18: =Articles!B17 | C18: =IF(A18="","",SUMIFS(Mouvements!$G:$G,Mouvements!$E:$E,$B$3,Mouvements!$B:$B,A18,Mouvements!$F:$F,"Départ")) | D18: =IF(A18="","",SUMIFS(Mouvements!$G:$G,Mouvements!$E:$E,$B$3,Mouvements!$B:$B,A18,Mouvements!$F:$F,"Retour")) | E18: =IF(A18="","",C18-D18) | G18: =IF(E18="","",IF(E18>0,"À récupérer","Soldé")) | I18: =IF(E18<0,"Retour > départ","")
A19: =Articles!A18 | B19: =Articles!B18 | C19: =IF(A19="","",SUMIFS(Mouvements!$G:$G,Mouvements!$E:$E,$B$3,Mouvements!$B:$B,A19,Mouvements!$F:$F,"Départ")) | D19: =IF(A19="","",SUMIFS(Mouvements!$G:$G,Mouvements!$E:$E,$B$3,Mouvements!$B:$B,A19,Mouvements!$F:$F,"Retour")) | E19: =IF(A19="","",C19-D19) | G19: =IF(E19="","",IF(E19>0,"À récupérer","Soldé")) | I19: =IF(E19<0,"Retour > départ","")
A20: =Articles!A19 | B20: =Articles!B19 | C20: =IF(A20="","",SUMIFS(Mouvements!$G:$G,Mouvements!$E:$E,$B$3,Mouvements!$B:$B,A20,Mouvements!$F:$F,"Départ")) | D20: =IF(A20="","",SUMIFS(Mouvements!$G:$G,Mouvements!$E:$E,$B$3,Mouvements!$B:$B,A20,Mouvements!$F:$F,"Retour")) | E20: =IF(A20="","",C20-D20) | G20: =IF(E20="","",IF(E20>0,"À récupérer","Soldé")) | I20: =IF(E20<0,"Retour > départ","")
A21: =Articles!A20 | B21: =Articles!B20 | C21: =IF(A21="","",SUMIFS(Mouvements!$G:$G,Mouvements!$E:$E,$B$3,Mouvements!$B:$B,A21,Mouvements!$F:$F,"Départ")) | D21: =IF(A21="","",SUMIFS(Mouvements!$G:$G,Mouvements!$E:$E,$B$3,Mouvements!$B:$B,A21,Mouvements!$F:$F,"Retour")) | E21: =IF(A21="","",C21-D21) | G21: =IF(E21="","",IF(E21>0,"À récupérer","Soldé")) | I21: =IF(E21<0,"Retour > départ","")
... A105: =Articles!A104 | B105: =Articles!B104 | C105: =IF(A105="","",SUMIFS(Mouvements!$G:$G,Mouvements!$E:$E,$B$3,Mouvements!$B:$B,A105,Mouvements!$F:$F,"Départ")) | D105: =IF(A105="","",SUMIFS(Mouvements!$G:$G,Mouvements!$E:$E,$B$3,Mouvements!$B:$B,A105,Mouvements!$F:$F,"Retour")) | E105: =IF(A105="","",C105-D105) | G105: =IF(E105="","",IF(E105>0,"À récupérer","Soldé")) | I105: =IF(E105<0,"Retour > départ","")

Sheet Chantier B
A1: Chantier B - suivi automatique
A2: Cette feuille se met à jour depuis Mouvements. Duplique-la pour un autre chantier et change B3.
A3: Chantier | B3: Chantier B
A5: Référence | B5: Désignation | C5: Départs | D5: Retours | E5: Reste chantier | F5: Dernière sortie | G5: Statut | H5: Observation | I5: Contrôle
A6: =Articles!A5 -> VIS-6X60 | B6: =Articles!B5 -> Vis béton 6x60 | C6: =IF(A6="","",SUMIFS(Mouvements!$G:$G,Mouvements!$E:$E,$B$3,Mouvements!$B:$B,A6,Mouvements!$F:$F,"Départ")) -> 0 | D6: =IF(A6="","",SUMIFS(Mouvements!$G:$G,Mouvements!$E:$E,$B$3,Mouvements!$B:$B,A6,Mouvements!$F:$F,"Retour")) -> 0 | E6: =IF(A6="","",C6-D6) -> 0 | G6: =IF(E6="","",IF(E6>0,"À récupérer","Soldé")) -> Soldé | I6: =IF(E6<0,"Retour > départ","")
A7: =Articles!A6 -> PERF-001 | B7: =Articles!B6 -> Perforateur SDS | C7: =IF(A7="","",SUMIFS(Mouvements!$G:$G,Mouvements!$E:$E,$B$3,Mouvements!$B:$B,A7,Mouvements!$F:$F,"Départ")) -> 0 | D7: =IF(A7="","",SUMIFS(Mouvements!$G:$G,Mouvements!$E:$E,$B$3,Mouvements!$B:$B,A7,Mouvements!$F:$F,"Retour")) -> 0 | E7: =IF(A7="","",C7-D7) -> 0 | G7: =IF(E7="","",IF(E7>0,"À récupérer","Soldé")) -> Soldé | I7: =IF(E7<0,"Retour > départ","")
A8: =Articles!A7 -> GANT-L | B8: =Articles!B7 -> Gants taille L | C8: =IF(A8="","",SUMIFS(Mouvements!$G:$G,Mouvements!$E:$E,$B$3,Mouvements!$B:$B,A8,Mouvements!$F:$F,"Départ")) -> 0 | D8: =IF(A8="","",SUMIFS(Mouvements!$G:$G,Mouvements!$E:$E,$B$3,Mouvements!$B:$B,A8,Mouvements!$F:$F,"Retour")) -> 0 | E8: =IF(A8="","",C8-D8) -> 0 | G8: =IF(E8="","",IF(E8>0,"À récupérer","Soldé")) -> Soldé | I8: =IF(E8<0,"Retour > départ","")
A9: =Articles!A8 -> 12345 | B9: =Articles!B8 -> Quentin | C9: =IF(A9="","",SUMIFS(Mouvements!$G:$G,Mouvements!$E:$E,$B$3,Mouvements!$B:$B,A9,Mouvements!$F:$F,"Départ")) -> 0 | D9: =IF(A9="","",SUMIFS(Mouvements!$G:$G,Mouvements!$E:$E,$B$3,Mouvements!$B:$B,A9,Mouvements!$F:$F,"Retour")) -> 0 | E9: =IF(A9="","",C9-D9) -> 0 | G9: =IF(E9="","",IF(E9>0,"À récupérer","Soldé")) -> Soldé | I9: =IF(E9<0,"Retour > départ","")
A10: =Articles!A9 -> 4969272 | B10: =Articles!B9 -> teben | C10: =IF(A10="","",SUMIFS(Mouvements!$G:$G,Mouvements!$E:$E,$B$3,Mouvements!$B:$B,A10,Mouvements!$F:$F,"Départ")) -> 0 | D10: =IF(A10="","",SUMIFS(Mouvements!$G:$G,Mouvements!$E:$E,$B$3,Mouvements!$B:$B,A10,Mouvements!$F:$F,"Retour")) -> 0 | E10: =IF(A10="","",C10-D10) -> 0 | G10: =IF(E10="","",IF(E10>0,"À récupérer","Soldé")) -> Soldé | I10: =IF(E10<0,"Retour > départ","")
A11: =Articles!A10 | B11: =Articles!B10 | C11: =IF(A11="","",SUMIFS(Mouvements!$G:$G,Mouvements!$E:$E,$B$3,Mouvements!$B:$B,A11,Mouvements!$F:$F,"Départ")) | D11: =IF(A11="","",SUMIFS(Mouvements!$G:$G,Mouvements!$E:$E,$B$3,Mouvements!$B:$B,A11,Mouvements!$F:$F,"Retour")) | E11: =IF(A11="","",C11-D11) | G11: =IF(E11="","",IF(E11>0,"À récupérer","Soldé")) | I11: =IF(E11<0,"Retour > départ","")
A12: =Articles!A11 | B12: =Articles!B11 | C12: =IF(A12="","",SUMIFS(Mouvements!$G:$G,Mouvements!$E:$E,$B$3,Mouvements!$B:$B,A12,Mouvements!$F:$F,"Départ")) | D12: =IF(A12="","",SUMIFS(Mouvements!$G:$G,Mouvements!$E:$E,$B$3,Mouvements!$B:$B,A12,Mouvements!$F:$F,"Retour")) | E12: =IF(A12="","",C12-D12) | G12: =IF(E12="","",IF(E12>0,"À récupérer","Soldé")) | I12: =IF(E12<0,"Retour > départ","")
A13: =Articles!A12 | B13: =Articles!B12 | C13: =IF(A13="","",SUMIFS(Mouvements!$G:$G,Mouvements!$E:$E,$B$3,Mouvements!$B:$B,A13,Mouvements!$F:$F,"Départ")) | D13: =IF(A13="","",SUMIFS(Mouvements!$G:$G,Mouvements!$E:$E,$B$3,Mouvements!$B:$B,A13,Mouvements!$F:$F,"Retour")) | E13: =IF(A13="","",C13-D13) | G13: =IF(E13="","",IF(E13>0,"À récupérer","Soldé")) | I13: =IF(E13<0,"Retour > départ","")
A14: =Articles!A13 | B14: =Articles!B13 | C14: =IF(A14="","",SUMIFS(Mouvements!$G:$G,Mouvements!$E:$E,$B$3,Mouvements!$B:$B,A14,Mouvements!$F:$F,"Départ")) | D14: =IF(A14="","",SUMIFS(Mouvements!$G:$G,Mouvements!$E:$E,$B$3,Mouvements!$B:$B,A14,Mouvements!$F:$F,"Retour")) | E14: =IF(A14="","",C14-D14) | G14: =IF(E14="","",IF(E14>0,"À récupérer","Soldé")) | I14: =IF(E14<0,"Retour > départ","")
A15: =Articles!A14 | B15: =Articles!B14 | C15: =IF(A15="","",SUMIFS(Mouvements!$G:$G,Mouvements!$E:$E,$B$3,Mouvements!$B:$B,A15,Mouvements!$F:$F,"Départ")) | D15: =IF(A15="","",SUMIFS(Mouvements!$G:$G,Mouvements!$E:$E,$B$3,Mouvements!$B:$B,A15,Mouvements!$F:$F,"Retour")) | E15: =IF(A15="","",C15-D15) | G15: =IF(E15="","",IF(E15>0,"À récupérer","Soldé")) | I15: =IF(E15<0,"Retour > départ","")
A16: =Articles!A15 | B16: =Articles!B15 | C16: =IF(A16="","",SUMIFS(Mouvements!$G:$G,Mouvements!$E:$E,$B$3,Mouvements!$B:$B,A16,Mouvements!$F:$F,"Départ")) | D16: =IF(A16="","",SUMIFS(Mouvements!$G:$G,Mouvements!$E:$E,$B$3,Mouvements!$B:$B,A16,Mouvements!$F:$F,"Retour")) | E16: =IF(A16="","",C16-D16) | G16: =IF(E16="","",IF(E16>0,"À récupérer","Soldé")) | I16: =IF(E16<0,"Retour > départ","")
A17: =Articles!A16 | B17: =Articles!B16 | C17: =IF(A17="","",SUMIFS(Mouvements!$G:$G,Mouvements!$E:$E,$B$3,Mouvements!$B:$B,A17,Mouvements!$F:$F,"Départ")) | D17: =IF(A17="","",SUMIFS(Mouvements!$G:$G,Mouvements!$E:$E,$B$3,Mouvements!$B:$B,A17,Mouvements!$F:$F,"Retour")) | E17: =IF(A17="","",C17-D17) | G17: =IF(E17="","",IF(E17>0,"À récupérer","Soldé")) | I17: =IF(E17<0,"Retour > départ","")
... A105: =Articles!A104 | B105: =Articles!B104 | C105: =IF(A105="","",SUMIFS(Mouvements!$G:$G,Mouvements!$E:$E,$B$3,Mouvements!$B:$B,A105,Mouvements!$F:$F,"Départ")) | D105: =IF(A105="","",SUMIFS(Mouvements!$G:$G,Mouvements!$E:$E,$B$3,Mouvements!$B:$B,A105,Mouvements!$F:$F,"Retour")) | E105: =IF(A105="","",C105-D105) | G105: =IF(E105="","",IF(E105>0,"À récupérer","Soldé")) | I105: =IF(E105<0,"Retour > départ","")

Sheet Chantier C
A1: Chantier C - suivi automatique
A2: Cette feuille se met à jour depuis Mouvements. Duplique-la pour un autre chantier et change B3.
A3: Chantier | B3: Chantier C
A5: Référence | B5: Désignation | C5: Départs | D5: Retours | E5: Reste chantier | F5: Dernière sortie | G5: Statut | H5: Observation | I5: Contrôle
